Workbook

Sheet READ ME
A1: PAID vs DESERVED: THE AFL PLAYER SALARY LEDGER, 2021-2025 (v1.1, stress-tested)
A3: WHAT THIS IS. For every player who took the field 2021-2023: what their production was worth at the league's market rate (DESERVED), versus a modelled estimate of what convention pays them (ESTIMATED PAY BAND), and the gap. Plus every club's cap position 2021-2025.
A5: READ THESE CAVEATS BEFORE QUOTING ANYTHING:
A6: 1. NO INDIVIDUAL AFL SALARY IS PUBLIC. Every per-player pay figure is a MODELLED ESTIMATE, in bands, never points. Not a report of any person's actual contract.
A7: 2. DESERVED = Player Value (validated +0.67 to +0.71 vs held-out Brownlow votes) priced at the league rate: (18 x cap) / total league Player Value.
A8: 3. ESTIMATED PAY models market behaviour: reputation (prior 3 seasons, weighted 50/30/20) mapped to bands calibrated to AFL published aggregates, WITH A CAREER FLOOR added after stress-testing: 100+ career games floors a player at the 55th pay percentile, 60+ at the 40th, 30+ at the 25th, because contracts persist through injury and veterans never earn rookie scale. (v1.0 modelled Wayne Milera at $140-250K; the floor fixed that class of error.)
A9: 4. THE GAP IS THE PRODUCT: pay lags production. Breakouts read UNDERPAID, fading reputations read OVERPAID. Stress-test result: 2023 UNDERPAID leaders are Gulden, Sheezel, Rowell, Serong, Curnow, Will Day and the young GWS/StK breakouts on development deals, which matches what football media reported. Known residual bias: established stars on reported $900K+ deals (Greene, Daniher) sit one band low until media contract anchors land at trade period.
A10: 5. COVERAGE: player ledger 2021-2023 complete; 2024-25 club level only via expected wins (EW PROXY), pending the production scraper.
A11: 6. 2021 cap COVID-adjusted, approximate (yellow). Clubs evaluated at 100% of cap (real spread 95-100%, max 1.05x).
A12: 7. Sources: AFL Tables box scores (community mirrors), Betfair exchange closing prices, AFL TPP releases, CBA 2023-27 Sch 2A. Career games counted from 2015 (pre-2015 service missing for the oldest veterans; their recent history dominates anyway). Built 13 June 2026.
A14: SHEETS: Assumptions (blue cells editable) | Player Ledger (live) | Club Cap Position | Headline Mismatches.
A16: Verdicts: UNDERPAID = deserved > band top +15%. OVERPAID = deserved < band floor -15%. FAIR inside. LOW SAMPLE = under 8 games.

Sheet Assumptions
A1: ASSUMPTIONS: EDIT BLUE CELLS
A3: Year | B3: Cap ($M) | C3: League PV (formula) | D3: Rate ($K per PV pt)
A4: 2021 | B4: 13 | C4: =SUMIFS('Player Ledger'!$E:$E,'Player Ledger'!$A:$A,2021) -> 1804.74 | D4: =18*B4*1000/C4 -> 129.65857
A5: 2022 | B5: 13.54 | C5: =SUMIFS('Player Ledger'!$E:$E,'Player Ledger'!$A:$A,2022) -> 1809.32 | D5: =18*B5*1000/C5 -> 134.70254
A6: 2023 | B6: 15.02 | C6: =SUMIFS('Player Ledger'!$E:$E,'Player Ledger'!$A:$A,2023) -> 1806.89 | D6: =18*B6*1000/C6 -> 149.62726
A7: 2024 | B7: 15.79 | C7: EW PROXY YEAR
A8: 2025 | B8: 17.8 | C8: EW PROXY YEAR
A10: Verdict threshold | B10: 0.15
A12: Career pay floor (games : min percentile): 100:55, 60:40, 30:25. Band ladder (2023 $K):
A13: 99.3 | B13: 1300 | C13: 1700
A14: 96.7 | B14: 950 | C14: 1300
A15: 88 | B15: 680 | C15: 950
A16: 70 | B16: 500 | C16: 680
A17: 47 | B17: 380 | C17: 500
A18: 22 | B18: 250 | C18: 380
A19: 0 | B19: 140 | C19: 250

Sheet Player Ledger
A1: Year | B1: Club | C1: Player | D1: Games | E1: Player Value (PV) | F1: Deserved ($K) | G1: Est Pay Low ($K) | H1: Est Pay High ($K) | I1: Gap vs Band Mid ($K) | J1: Verdict | K1: Career Games (pre-season)
A2: 2021 | B2: Adelaide | C2: Andrew McPherson | D2: 18 | E2: 2.23 | F2: =E2*Assumptions!$D$4 -> 289.1386 | G2: 120 | H2: 215 | I2: =F2-(G2+H2)/2 -> 121.6386 | J2: =IF(D2<8,"LOW SAMPLE",IF(F2>H2*(1+Assumptions!$B$10),"UNDERPAID",IF(F2<G2*(1-Assumptions!$B$10),"OVERPAID","FAIR"))) -> UNDERPAID | K2: 9
A3: 2021 | B3: Adelaide | C3: Ben Davis | D3: 4 | E3: 0.21 | F3: =E3*Assumptions!$D$4 -> 27.228299 | G3: 120 | H3: 215 | I3: =F3-(G3+H3)/2 -> -140.2717 | J3: =IF(D3<8,"LOW SAMPLE",IF(F3>H3*(1+Assumptions!$B$10),"UNDERPAID",IF(F3<G3*(1-Assumptions!$B$10),"OVERPAID","FAIR"))) -> LOW SAMPLE | K3: 2
A4: 2021 | B4: Adelaide | C4: Ben Keays | D4: 22 | E4: 6.76 | F4: =E4*Assumptions!$D$4 -> 876.4919 | G4: 215 | H4: 330 | I4: =F4-(G4+H4)/2 -> 603.9919 | J4: =IF(D4<8,"LOW SAMPLE",IF(F4>H4*(1+Assumptions!$B$10),"UNDERPAID",IF(F4<G4*(1-Assumptions!$B$10),"OVERPAID","FAIR"))) -> UNDERPAID | K4: 46
A5: 2021 | B5: Adelaide | C5: Billy Frampton | D5: 10 | E5: 1.46 | F5: =E5*Assumptions!$D$4 -> 189.30151 | G5: 120 | H5: 215 | I5: =F5-(G5+H5)/2 -> 21.801506 | J5: =IF(D5<8,"LOW SAMPLE",IF(F5>H5*(1+Assumptions!$B$10),"UNDERPAID",IF(F5<G5*(1-Assumptions!$B$10),"OVERPAID","FAIR"))) -> FAIR | K5: 8
A6: 2021 | B6: Adelaide | C6: Brayden Cook | D6: 3 | E6: 0.21 | F6: =E6*Assumptions!$D$4 -> 27.228299 | G6: 215 | H6: 330 | I6: =F6-(G6+H6)/2 -> -245.2717 | J6: =IF(D6<8,"LOW SAMPLE",IF(F6>H6*(1+Assumptions!$B$10),"UNDERPAID",IF(F6<G6*(1-Assumptions!$B$10),"OVERPAID","FAIR"))) -> LOW SAMPLE | K6: 0
A7: 2021 | B7: Adelaide | C7: Brodie Smith | D7: 21 | E7: 4.96 | F7: =E7*Assumptions!$D$4 -> 643.10649 | G7: 435 | H7: 590 | I7: =F7-(G7+H7)/2 -> 130.60649 | J7: =IF(D7<8,"LOW SAMPLE",IF(F7>H7*(1+Assumptions!$B$10),"UNDERPAID",IF(F7<G7*(1-Assumptions!$B$10),"OVERPAID","FAIR"))) -> FAIR | K7: 107
A8: 2021 | B8: Adelaide | C8: Chayce Jones | D8: 15 | E8: 1.78 | F8: =E8*Assumptions!$D$4 -> 230.79225 | G8: 215 | H8: 330 | I8: =F8-(G8+H8)/2 -> -41.707753 | J8: =IF(D8<8,"LOW SAMPLE",IF(F8>H8*(1+Assumptions!$B$10),"UNDERPAID",IF(F8<G8*(1-Assumptions!$B$10),"OVERPAID","FAIR"))) -> FAIR | K8: 23
A9: 2021 | B9: Adelaide | C9: Darcy Fogarty | D9: 17 | E9: 3.04 | F9: =E9*Assumptions!$D$4 -> 394.16204 | G9: 215 | H9: 330 | I9: =F9-(G9+H9)/2 -> 121.66204 | J9: =IF(D9<8,"LOW SAMPLE",IF(F9>H9*(1+Assumptions!$B$10),"UNDERPAID",IF(F9<G9*(1-Assumptions!$B$10),"OVERPAID","FAIR"))) -> UNDERPAID | K9: 24
A10: 2021 | B10: Adelaide | C10: David Mackay | D10: 18 | E10: 2.37 | F10: =E10*Assumptions!$D$4 -> 307.2908 | G10: 330 | H10: 435 | I10: =F10-(G10+H10)/2 -> -75.209199 | J10: =IF(D10<8,"LOW SAMPLE",IF(F10>H10*(1+Assumptions!$B$10),"UNDERPAID",IF(F10<G10*(1-Assumptions!$B$10),"OVERPAID","FAIR"))) -> FAIR | K10: 106
A11: 2021 | B11: Adelaide | C11: Elliott Himmelberg | D11: 8 | E11: 1.45 | F11: =E11*Assumptions!$D$4 -> 188.00492 | G11: 215 | H11: 330 | I11: =F11-(G11+H11)/2 -> -84.49508 | J11: =IF(D11<8,"LOW SAMPLE",IF(F11>H11*(1+Assumptions!$B$10),"UNDERPAID",IF(F11<G11*(1-Assumptions!$B$10),"OVERPAID","FAIR"))) -> FAIR | K11: 19
A12: 2021 | B12: Adelaide | C12: Harry Schoenberg | D12: 22 | E12: 4.44 | F12: =E12*Assumptions!$D$4 -> 575.68403 | G12: 120 | H12: 215 | I12: =F12-(G12+H12)/2 -> 408.18403 | J12: =IF(D12<8,"LOW SAMPLE",IF(F12>H12*(1+Assumptions!$B$10),"UNDERPAID",IF(F12<G12*(1-Assumptions!$B$10),"OVERPAID","FAIR"))) -> UNDERPAID | K12: 8
A13: 2021 | B13: Adelaide | C13: Jackson Hately | D13: 3 | E13: 0.31 | F13: =E13*Assumptions!$D$4 -> 40.194155 | G13: 120 | H13: 215 | I13: =F13-(G13+H13)/2 -> -127.30584 | J13: =IF(D13<8,"LOW SAMPLE",IF(F13>H13*(1+Assumptions!$B$10),"UNDERPAID",IF(F13<G13*(1-Assumptions!$B$10),"OVERPAID","FAIR"))) -> LOW SAMPLE | K13: 13
... A675: 2021 | B675: Western Bulldogs | C675: Zaine Cordy | D675: 19 | E675: 2.95 | F675: =E675*Assumptions!$D$4 -> 382.49277 | G675: 330 | H675: 435 | I675: =F675-(G675+H675)/2 -> -0.0072309585 | J675: =IF(D675<8,"LOW SAMPLE",IF(F675>H675*(1+Assumptions!$B$10),"UNDERPAID",IF(F675<G675*(1-Assumptions!$B$10),"OVERPAID","FAIR"))) -> FAIR | K675: 85
A676: 2022 | B676: Adelaide | C676: Andrew McPherson | D676: 1 | E676: 0.08 | F676: =E676*Assumptions!$D$5 -> 10.776203 | G676: 225 | H676: 345 | I676: =F676-(G676+H676)/2 -> -274.2238 | J676: =IF(D676<8,"LOW SAMPLE",IF(F676>H676*(1+Assumptions!$B$10),"UNDERPAID",IF(F676<G676*(1-Assumptions!$B$10),"OVERPAID","FAIR"))) -> LOW SAMPLE | K676: 27
A677: 2022 | B677: Adelaide | C677: Ben Davis | D677: 5 | E677: 0.15 | F677: =E677*Assumptions!$D$5 -> 20.205381 | G677: 125 | H677: 225 | I677: =F677-(G677+H677)/2 -> -154.79462 | J677: =IF(D677<8,"LOW SAMPLE",IF(F677>H677*(1+Assumptions!$B$10),"UNDERPAID",IF(F677<G677*(1-Assumptions!$B$10),"OVERPAID","FAIR"))) -> LOW SAMPLE | K677: 6
A678: 2022 | B678: Adelaide | C678: Ben Keays | D678: 22 | E678: 5.8 | F678: =E678*Assumptions!$D$5 -> 781.27473 | G678: 450 | H678: 615 | I678: =F678-(G678+H678)/2 -> 248.77473 | J678: =IF(D678<8,"LOW SAMPLE",IF(F678>H678*(1+Assumptions!$B$10),"UNDERPAID",IF(F678<G678*(1-Assumptions!$B$10),"OVERPAID","FAIR"))) -> UNDERPAID | K678: 68
A679: 2022 | B679: Adelaide | C679: Billy Frampton | D679: 6 | E679: 1.28 | F679: =E679*Assumptions!$D$5 -> 172.41925 | G679: 125 | H679: 225 | I679: =F679-(G679+H679)/2 -> -2.5807486 | J679: =IF(D679<8,"LOW SAMPLE",IF(F679>H679*(1+Assumptions!$B$10),"UNDERPAID",IF(F679<G679*(1-Assumptions!$B$10),"OVERPAID","FAIR"))) -> LOW SAMPLE | K679: 18
A680: 2022 | B680: Adelaide | C680: Brayden Cook | D680: 8 | E680: 0.7 | F680: =E680*Assumptions!$D$5 -> 94.291778 | G680: 125 | H680: 225 | I680: =F680-(G680+H680)/2 -> -80.708222 | J680: =IF(D680<8,"LOW SAMPLE",IF(F680>H680*(1+Assumptions!$B$10),"UNDERPAID",IF(F680<G680*(1-Assumptions!$B$10),"OVERPAID","FAIR"))) -> OVERPAID | K680: 3
A681: 2022 | B681: Adelaide | C681: Brodie Smith | D681: 21 | E681: 4.44 | F681: =E681*Assumptions!$D$5 -> 598.07928 | G681: 615 | H681: 855 | I681: =F681-(G681+H681)/2 -> -136.92072 | J681: =IF(D681<8,"LOW SAMPLE",IF(F681>H681*(1+Assumptions!$B$10),"UNDERPAID",IF(F681<G681*(1-Assumptions!$B$10),"OVERPAID","FAIR"))) -> FAIR | K681: 128
A682: 2022 | B682: Adelaide | C682: Chayce Jones | D682: 20 | E682: 2.44 | F682: =E682*Assumptions!$D$5 -> 328.6742 | G682: 225 | H682: 345 | I682: =F682-(G682+H682)/2 -> 43.674198 | J682: =IF(D682<8,"LOW SAMPLE",IF(F682>H682*(1+Assumptions!$B$10),"UNDERPAID",IF(F682<G682*(1-Assumptions!$B$10),"OVERPAID","FAIR"))) -> FAIR | K682: 38
A683: 2022 | B683: Adelaide | C683: Darcy Fogarty | D683: 17 | E683: 4 | F683: =E683*Assumptions!$D$5 -> 538.81016 | G683: 345 | H683: 450 | I683: =F683-(G683+H683)/2 -> 141.31016 | J683: =IF(D683<8,"LOW SAMPLE",IF(F683>H683*(1+Assumptions!$B$10),"UNDERPAID",IF(F683<G683*(1-Assumptions!$B$10),"OVERPAID","FAIR"))) -> UNDERPAID | K683: 41
A684: 2022 | B684: Adelaide | C684: Elliott Himmelberg | D684: 11 | E684: 2.06 | F684: =E684*Assumptions!$D$5 -> 277.48723 | G684: 225 | H684: 345 | I684: =F684-(G684+H684)/2 -> -7.5127672 | J684: =IF(D684<8,"LOW SAMPLE",IF(F684>H684*(1+Assumptions!$B$10),"UNDERPAID",IF(F684<G684*(1-Assumptions!$B$10),"OVERPAID","FAIR"))) -> FAIR | K684: 27
A685: 2022 | B685: Adelaide | C685: Harry Schoenberg | D685: 16 | E685: 2.98 | F685: =E685*Assumptions!$D$5 -> 401.41357 | G685: 345 | H685: 450 | I685: =F685-(G685+H685)/2 -> 3.9135697 | J685: =IF(D685<8,"LOW SAMPLE",IF(F685>H685*(1+Assumptions!$B$10),"UNDERPAID",IF(F685<G685*(1-Assumptions!$B$10),"OVERPAID","FAIR"))) -> FAIR | K685: 30
A686: 2022 | B686: Adelaide | C686: Jackson Hately | D686: 11 | E686: 1.83 | F686: =E686*Assumptions!$D$5 -> 246.50565 | G686: 125 | H686: 225 | I686: =F686-(G686+H686)/2 -> 71.505649 | J686: =IF(D686<8,"LOW SAMPLE",IF(F686>H686*(1+Assumptions!$B$10),"UNDERPAID",IF(F686<G686*(1-Assumptions!$B$10),"OVERPAID","FAIR"))) -> FAIR | K686: 16
A687: 2022 | B687: Adelaide | C687: Jake Soligo | D687: 16 | E687: 2.52 | F687: =E687*Assumptions!$D$5 -> 339.4504 | G687: 225 | H687: 345 | I687: =F687-(G687+H687)/2 -> 54.450401 | J687: =IF(D687<8,"LOW SAMPLE",IF(F687>H687*(1+Assumptions!$B$10),"UNDERPAID",IF(F687<G687*(1-Assumptions!$B$10),"OVERPAID","FAIR"))) -> FAIR | K687: 0
... A1359: 2022 | B1359: Western Bulldogs | C1359: Zaine Cordy | D1359: 14 | E1359: 1.89 | F1359: =E1359*Assumptions!$D$5 -> 254.5878 | G1359: 345 | H1359: 450 | I1359: =F1359-(G1359+H1359)/2 -> -142.9122 | J1359: =IF(D1359<8,"LOW SAMPLE",IF(F1359>H1359*(1+Assumptions!$B$10),"UNDERPAID",IF(F1359<G1359*(1-Assumptions!$B$10),"OVERPAID","FAIR"))) -> OVERPAID | K1359: 104
A1360: 2023 | B1360: Adelaide | C1360: Ben Keays | D1360: 23 | E1360: 5.09 | F1360: =E1360*Assumptions!$D$6 -> 761.60275 | G1360: 680 | H1360: 950 | I1360: =F1360-(G1360+H1360)/2 -> -53.397246 | J1360: =IF(D1360<8,"LOW SAMPLE",IF(F1360>H1360*(1+Assumptions!$B$10),"UNDERPAID",IF(F1360<G1360*(1-Assumptions!$B$10),"OVERPAID","FAIR"))) -> FAIR | K1360: 90
A1361: 2023 | B1361: Adelaide | C1361: Brayden Cook | D1361: 1 | E1361: 0.2 | F1361: =E1361*Assumptions!$D$6 -> 29.925452 | G1361: 140 | H1361: 250 | I1361: =F1361-(G1361+H1361)/2 -> -165.07455 | J1361: =IF(D1361<8,"LOW SAMPLE",IF(F1361>H1361*(1+Assumptions!$B$10),"UNDERPAID",IF(F1361<G1361*(1-Assumptions!$B$10),"OVERPAID","FAIR"))) -> LOW SAMPLE | K1361: 11
A1362: 2023 | B1362: Adelaide | C1362: Brodie Smith | D1362: 22 | E1362: 4.85 | F1362: =E1362*Assumptions!$D$6 -> 725.69221 | G1362: 500 | H1362: 680 | I1362: =F1362-(G1362+H1362)/2 -> 135.69221 | J1362: =IF(D1362<8,"LOW SAMPLE",IF(F1362>H1362*(1+Assumptions!$B$10),"UNDERPAID",IF(F1362<G1362*(1-Assumptions!$B$10),"OVERPAID","FAIR"))) -> FAIR | K1362: 149
A1363: 2023 | B1363: Adelaide | C1363: Chayce Jones | D1363: 18 | E1363: 3.67 | F1363: =E1363*Assumptions!$D$6 -> 549.13204 | G1363: 250 | H1363: 380 | I1363: =F1363-(G1363+H1363)/2 -> 234.13204 | J1363: =IF(D1363<8,"LOW SAMPLE",IF(F1363>H1363*(1+Assumptions!$B$10),"UNDERPAID",IF(F1363<G1363*(1-Assumptions!$B$10),"OVERPAID","FAIR"))) -> UNDERPAID | K1363: 58
A1364: 2023 | B1364: Adelaide | C1364: Darcy Fogarty | D1364: 21 | E1364: 4.48 | F1364: =E1364*Assumptions!$D$6 -> 670.33013 | G1364: 380 | H1364: 500 | I1364: =F1364-(G1364+H1364)/2 -> 230.33013 | J1364: =IF(D1364<8,"LOW SAMPLE",IF(F1364>H1364*(1+Assumptions!$B$10),"UNDERPAID",IF(F1364<G1364*(1-Assumptions!$B$10),"OVERPAID","FAIR"))) -> UNDERPAID | K1364: 58
A1365: 2023 | B1365: Adelaide | C1365: Elliott Himmelberg | D1365: 3 | E1365: 0.43 | F1365: =E1365*Assumptions!$D$6 -> 64.339722 | G1365: 250 | H1365: 380 | I1365: =F1365-(G1365+H1365)/2 -> -250.66028 | J1365: =IF(D1365<8,"LOW SAMPLE",IF(F1365>H1365*(1+Assumptions!$B$10),"UNDERPAID",IF(F1365<G1365*(1-Assumptions!$B$10),"OVERPAID","FAIR"))) -> LOW SAMPLE | K1365: 38
A1366: 2023 | B1366: Adelaide | C1366: Harry Schoenberg | D1366: 11 | E1366: 1.52 | F1366: =E1366*Assumptions!$D$6 -> 227.43344 | G1366: 380 | H1366: 500 | I1366: =F1366-(G1366+H1366)/2 -> -212.56656 | J1366: =IF(D1366<8,"LOW SAMPLE",IF(F1366>H1366*(1+Assumptions!$B$10),"UNDERPAID",IF(F1366<G1366*(1-Assumptions!$B$10),"OVERPAID","FAIR"))) -> OVERPAID | K1366: 46
A1367: 2023 | B1367: Adelaide | C1367: Izak Rankine | D1367: 20 | E1367: 5.08 | F1367: =E1367*Assumptions!$D$6 -> 760.10648 | G1367: 380 | H1367: 500 | I1367: =F1367-(G1367+H1367)/2 -> 320.10648 | J1367: =IF(D1367<8,"LOW SAMPLE",IF(F1367>H1367*(1+Assumptions!$B$10),"UNDERPAID",IF(F1367<G1367*(1-Assumptions!$B$10),"OVERPAID","FAIR"))) -> UNDERPAID | K1367: 48
A1368: 2023 | B1368: Adelaide | C1368: Jackson Hately | D1368: 1 | E1368: 0.03 | F1368: =E1368*Assumptions!$D$6 -> 4.4888178 | G1368: 140 | H1368: 250 | I1368: =F1368-(G1368+H1368)/2 -> -190.51118 | J1368: =IF(D1368<8,"LOW SAMPLE",IF(F1368>H1368*(1+Assumptions!$B$10),"UNDERPAID",IF(F1368<G1368*(1-Assumptions!$B$10),"OVERPAID","FAIR"))) -> LOW SAMPLE | K1368: 27
A1369: 2023 | B1369: Adelaide | C1369: Jake Soligo | D1369: 21 | E1369: 4.01 | F1369: =E1369*Assumptions!$D$6 -> 600.00531 | G1369: 380 | H1369: 500 | I1369: =F1369-(G1369+H1369)/2 -> 160.00531 | J1369: =IF(D1369<8,"LOW SAMPLE",IF(F1369>H1369*(1+Assumptions!$B$10),"UNDERPAID",IF(F1369<G1369*(1-Assumptions!$B$10),"OVERPAID","FAIR"))) -> UNDERPAID | K1369: 16
A1370: 2023 | B1370: Adelaide | C1370: James Borlase | D1370: 4 | E1370: 0.55 | F1370: =E1370*Assumptions!$D$6 -> 82.294993 | G1370: 250 | H1370: 380 | I1370: =F1370-(G1370+H1370)/2 -> -232.70501 | J1370: =IF(D1370<8,"LOW SAMPLE",IF(F1370>H1370*(1+Assumptions!$B$10),"UNDERPAID",IF(F1370<G1370*(1-Assumptions!$B$10),"OVERPAID","FAIR"))) -> LOW SAMPLE | K1370: 0
A1371: 2023 | B1371: Adelaide | C1371: Jordan Dawson | D1371: 23 | E1371: 6.93 | F1371: =E1371*Assumptions!$D$6 -> 1036.9169 | G1371: 950 | H1371: 1300 | I1371: =F1371-(G1371+H1371)/2 -> -88.083088 | J1371: =IF(D1371<8,"LOW SAMPLE",IF(F1371>H1371*(1+Assumptions!$B$10),"UNDERPAID",IF(F1371<G1371*(1-Assumptions!$B$10),"OVERPAID","FAIR"))) -> FAIR | K1371: 86
... A2022: 2023 | B2022: Western Bulldogs | C2022: Tom Liberatore | D2022: 21 | E2022: 6.62 | F2022: =E2022*Assumptions!$D$6 -> 990.53246 | G2022: 950 | H2022: 1300 | I2022: =F2022-(G2022+H2022)/2 -> -134.46754 | J2022: =IF(D2022<8,"LOW SAMPLE",IF(F2022>H2022*(1+Assumptions!$B$10),"UNDERPAID",IF(F2022<G2022*(1-Assumptions!$B$10),"OVERPAID","FAIR"))) -> FAIR | K2022: 118

Sheet Club Cap Position
A1: Year | B1: Club | C1: Basis | D1: List Worth ($M) | E1: Cap ($M) | F1: Surplus ($M) | G1: Surplus (%) | H1: Verdict | I1: EW (helper)
A2: 2021 | B2: Adelaide | C2: PV | D2: =SUMIFS('Player Ledger'!$E:$E,'Player Ledger'!$A:$A,2021,'Player Ledger'!$B:$B,B2)*Assumptions!$D$4/1000 -> 12.043984 | E2: =Assumptions!$B$4 -> 13 | F2: =D2-E2 -> -0.95601582 | G2: =D2/E2-1 -> -0.073539679 | H2: =IF(F2>0.05*E2,"LIST WORTH MORE THAN CAP: BOUGHT WELL, CANNOT AFFORD OWN PLAYERS AT FAIR VALUE",IF(F2<-0.05*E2,"LIST WORTH LESS THAN CAP: PAYING OVERS AS A GROUP","ROUGHLY FAIR VALUE")) -> LIST WORTH LESS THAN CAP: PAYING OVERS AS A GROUP
A3: 2021 | B3: Brisbane | C3: PV | D3: =SUMIFS('Player Ledger'!$E:$E,'Player Ledger'!$A:$A,2021,'Player Ledger'!$B:$B,B3)*Assumptions!$D$4/1000 -> 14.583995 | E3: =Assumptions!$B$4 -> 13 | F3: =D3-E3 -> 1.5839955 | G3: =D3/E3-1 -> 0.12184581 | H3: =IF(F3>0.05*E3,"LIST WORTH MORE THAN CAP: BOUGHT WELL, CANNOT AFFORD OWN PLAYERS AT FAIR VALUE",IF(F3<-0.05*E3,"LIST WORTH LESS THAN CAP: PAYING OVERS AS A GROUP","ROUGHLY FAIR VALUE")) -> LIST WORTH MORE THAN CAP: BOUGHT WELL, CANNOT AFFORD OWN PLAYERS AT FAIR VALUE
A4: 2021 | B4: Carlton | C4: PV | D4: =SUMIFS('Player Ledger'!$E:$E,'Player Ledger'!$A:$A,2021,'Player Ledger'!$B:$B,B4)*Assumptions!$D$4/1000 -> 12.401842 | E4: =Assumptions!$B$4 -> 13 | F4: =D4-E4 -> -0.59815818 | G4: =D4/E4-1 -> -0.046012168 | H4: =IF(F4>0.05*E4,"LIST WORTH MORE THAN CAP: BOUGHT WELL, CANNOT AFFORD OWN PLAYERS AT FAIR VALUE",IF(F4<-0.05*E4,"LIST WORTH LESS THAN CAP: PAYING OVERS AS A GROUP","ROUGHLY FAIR VALUE")) -> ROUGHLY FAIR VALUE
A5: 2021 | B5: Collingwood | C5: PV | D5: =SUMIFS('Player Ledger'!$E:$E,'Player Ledger'!$A:$A,2021,'Player Ledger'!$B:$B,B5)*Assumptions!$D$4/1000 -> 11.951927 | E5: =Assumptions!$B$4 -> 13 | F5: =D5-E5 -> -1.0480734 | G5: =D5/E5-1 -> -0.080621031 | H5: =IF(F5>0.05*E5,"LIST WORTH MORE THAN CAP: BOUGHT WELL, CANNOT AFFORD OWN PLAYERS AT FAIR VALUE",IF(F5<-0.05*E5,"LIST WORTH LESS THAN CAP: PAYING OVERS AS A GROUP","ROUGHLY FAIR VALUE")) -> LIST WORTH LESS THAN CAP: PAYING OVERS AS A GROUP
A6: 2021 | B6: Essendon | C6: PV | D6: =SUMIFS('Player Ledger'!$E:$E,'Player Ledger'!$A:$A,2021,'Player Ledger'!$B:$B,B6)*Assumptions!$D$4/1000 -> 13.369095 | E6: =Assumptions!$B$4 -> 13 | F6: =D6-E6 -> 0.36909472 | G6: =D6/E6-1 -> 0.028391901 | H6: =IF(F6>0.05*E6,"LIST WORTH MORE THAN CAP: BOUGHT WELL, CANNOT AFFORD OWN PLAYERS AT FAIR VALUE",IF(F6<-0.05*E6,"LIST WORTH LESS THAN CAP: PAYING OVERS AS A GROUP","ROUGHLY FAIR VALUE")) -> ROUGHLY FAIR VALUE
A7: 2021 | B7: Fremantle | C7: PV | D7: =SUMIFS('Player Ledger'!$E:$E,'Player Ledger'!$A:$A,2021,'Player Ledger'!$B:$B,B7)*Assumptions!$D$4/1000 -> 12.364241 | E7: =Assumptions!$B$4 -> 13 | F7: =D7-E7 -> -0.63575917 | G7: =D7/E7-1 -> -0.048904551 | H7: =IF(F7>0.05*E7,"LIST WORTH MORE THAN CAP: BOUGHT WELL, CANNOT AFFORD OWN PLAYERS AT FAIR VALUE",IF(F7<-0.05*E7,"LIST WORTH LESS THAN CAP: PAYING OVERS AS A GROUP","ROUGHLY FAIR VALUE")) -> ROUGHLY FAIR VALUE
A8: 2021 | B8: GWS | C8: PV | D8: =SUMIFS('Player Ledger'!$E:$E,'Player Ledger'!$A:$A,2021,'Player Ledger'!$B:$B,B8)*Assumptions!$D$4/1000 -> 12.766182 | E8: =Assumptions!$B$4 -> 13 | F8: =D8-E8 -> -0.23381761 | G8: =D8/E8-1 -> -0.01798597 | H8: =IF(F8>0.05*E8,"LIST WORTH MORE THAN CAP: BOUGHT WELL, CANNOT AFFORD OWN PLAYERS AT FAIR VALUE",IF(F8<-0.05*E8,"LIST WORTH LESS THAN CAP: PAYING OVERS AS A GROUP","ROUGHLY FAIR VALUE")) -> ROUGHLY FAIR VALUE
A9: 2021 | B9: Geelong | C9: PV | D9: =SUMIFS('Player Ledger'!$E:$E,'Player Ledger'!$A:$A,2021,'Player Ledger'!$B:$B,B9)*Assumptions!$D$4/1000 -> 13.816417 | E9: =Assumptions!$B$4 -> 13 | F9: =D9-E9 -> 0.81641677 | G9: =D9/E9-1 -> 0.06280129 | H9: =IF(F9>0.05*E9,"LIST WORTH MORE THAN CAP: BOUGHT WELL, CANNOT AFFORD OWN PLAYERS AT FAIR VALUE",IF(F9<-0.05*E9,"LIST WORTH LESS THAN CAP: PAYING OVERS AS A GROUP","ROUGHLY FAIR VALUE")) -> LIST WORTH MORE THAN CAP: BOUGHT WELL, CANNOT AFFORD OWN PLAYERS AT FAIR VALUE
A10: 2021 | B10: Gold Coast | C10: PV | D10: =SUMIFS('Player Ledger'!$E:$E,'Player Ledger'!$A:$A,2021,'Player Ledger'!$B:$B,B10)*Assumptions!$D$4/1000 -> 11.715948 | E10: =Assumptions!$B$4 -> 13 | F10: =D10-E10 -> -1.284052 | G10: =D10/E10-1 -> -0.09877323 | H10: =IF(F10>0.05*E10,"LIST WORTH MORE THAN CAP: BOUGHT WELL, CANNOT AFFORD OWN PLAYERS AT FAIR VALUE",IF(F10<-0.05*E10,"LIST WORTH LESS THAN CAP: PAYING OVERS AS A GROUP","ROUGHLY FAIR VALUE")) -> LIST WORTH LESS THAN CAP: PAYING OVERS AS A GROUP
A11: 2021 | B11: Hawthorn | C11: PV | D11: =SUMIFS('Player Ledger'!$E:$E,'Player Ledger'!$A:$A,2021,'Player Ledger'!$B:$B,B11)*Assumptions!$D$4/1000 -> 12.10622 | E11: =Assumptions!$B$4 -> 13 | F11: =D11-E11 -> -0.89377971 | G11: =D11/E11-1 -> -0.068752286 | H11: =IF(F11>0.05*E11,"LIST WORTH MORE THAN CAP: BOUGHT WELL, CANNOT AFFORD OWN PLAYERS AT FAIR VALUE",IF(F11<-0.05*E11,"LIST WORTH LESS THAN CAP: PAYING OVERS AS A GROUP","ROUGHLY FAIR VALUE")) -> LIST WORTH LESS THAN CAP: PAYING OVERS AS A GROUP
A12: 2021 | B12: Melbourne | C12: PV | D12: =SUMIFS('Player Ledger'!$E:$E,'Player Ledger'!$A:$A,2021,'Player Ledger'!$B:$B,B12)*Assumptions!$D$4/1000 -> 14.980751 | E12: =Assumptions!$B$4 -> 13 | F12: =D12-E12 -> 1.9807507 | G12: =D12/E12-1 -> 0.15236544 | H12: =IF(F12>0.05*E12,"LIST WORTH MORE THAN CAP: BOUGHT WELL, CANNOT AFFORD OWN PLAYERS AT FAIR VALUE",IF(F12<-0.05*E12,"LIST WORTH LESS THAN CAP: PAYING OVERS AS A GROUP","ROUGHLY FAIR VALUE")) -> LIST WORTH MORE THAN CAP: BOUGHT WELL, CANNOT AFFORD OWN PLAYERS AT FAIR VALUE
A13: 2021 | B13: North Melbourne | C13: PV | D13: =SUMIFS('Player Ledger'!$E:$E,'Player Ledger'!$A:$A,2021,'Player Ledger'!$B:$B,B13)*Assumptions!$D$4/1000 -> 11.254364 | E13: =Assumptions!$B$4 -> 13 | F13: =D13-E13 -> -1.7456365 | G13: =D13/E13-1 -> -0.13427973 | H13: =IF(F13>0.05*E13,"LIST WORTH MORE THAN CAP: BOUGHT WELL, CANNOT AFFORD OWN PLAYERS AT FAIR VALUE",IF(F13<-0.05*E13,"LIST WORTH LESS THAN CAP: PAYING OVERS AS A GROUP","ROUGHLY FAIR VALUE")) -> LIST WORTH LESS THAN CAP: PAYING OVERS AS A GROUP
... A19: 2021 | B19: Western Bulldogs | C19: PV | D19: =SUMIFS('Player Ledger'!$E:$E,'Player Ledger'!$A:$A,2021,'Player Ledger'!$B:$B,B19)*Assumptions!$D$4/1000 -> 14.494531 | E19: =Assumptions!$B$4 -> 13 | F19: =D19-E19 -> 1.4945311 | G19: =D19/E19-1 -> 0.11496393 | H19: =IF(F19>0.05*E19,"LIST WORTH MORE THAN CAP: BOUGHT WELL, CANNOT AFFORD OWN PLAYERS AT FAIR VALUE",IF(F19<-0.05*E19,"LIST WORTH LESS THAN CAP: PAYING OVERS AS A GROUP","ROUGHLY FAIR VALUE")) -> LIST WORTH MORE THAN CAP: BOUGHT WELL, CANNOT AFFORD OWN PLAYERS AT FAIR VALUE
A20: 2022 | B20: Adelaide | C20: PV | D20: =SUMIFS('Player Ledger'!$E:$E,'Player Ledger'!$A:$A,2022,'Player Ledger'!$B:$B,B20)*Assumptions!$D$5/1000 -> 12.71592 | E20: =Assumptions!$B$5 -> 13.54 | F20: =D20-E20 -> -0.82408021 | G20: =D20/E20-1 -> -0.060862645 | H20: =IF(F20>0.05*E20,"LIST WORTH MORE THAN CAP: BOUGHT WELL, CANNOT AFFORD OWN PLAYERS AT FAIR VALUE",IF(F20<-0.05*E20,"LIST WORTH LESS THAN CAP: PAYING OVERS AS A GROUP","ROUGHLY FAIR VALUE")) -> LIST WORTH LESS THAN CAP: PAYING OVERS AS A GROUP
A21: 2022 | B21: Brisbane | C21: PV | D21: =SUMIFS('Player Ledger'!$E:$E,'Player Ledger'!$A:$A,2022,'Player Ledger'!$B:$B,B21)*Assumptions!$D$5/1000 -> 14.41856 | E21: =Assumptions!$B$5 -> 13.54 | F21: =D21-E21 -> 0.8785599 | G21: =D21/E21-1 -> 0.064886256 | H21: =IF(F21>0.05*E21,"LIST WORTH MORE THAN CAP: BOUGHT WELL, CANNOT AFFORD OWN PLAYERS AT FAIR VALUE",IF(F21<-0.05*E21,"LIST WORTH LESS THAN CAP: PAYING OVERS AS A GROUP","ROUGHLY FAIR VALUE")) -> LIST WORTH MORE THAN CAP: BOUGHT WELL, CANNOT AFFORD OWN PLAYERS AT FAIR VALUE
A22: 2022 | B22: Carlton | C22: PV | D22: =SUMIFS('Player Ledger'!$E:$E,'Player Ledger'!$A:$A,2022,'Player Ledger'!$B:$B,B22)*Assumptions!$D$5/1000 -> 14.084498 | E22: =Assumptions!$B$5 -> 13.54 | F22: =D22-E22 -> 0.5444976 | G22: =D22/E22-1 -> 0.040214003 | H22: =IF(F22>0.05*E22,"LIST WORTH MORE THAN CAP: BOUGHT WELL, CANNOT AFFORD OWN PLAYERS AT FAIR VALUE",IF(F22<-0.05*E22,"LIST WORTH LESS THAN CAP: PAYING OVERS AS A GROUP","ROUGHLY FAIR VALUE")) -> ROUGHLY FAIR VALUE
A23: 2022 | B23: Collingwood | C23: PV | D23: =SUMIFS('Player Ledger'!$E:$E,'Player Ledger'!$A:$A,2022,'Player Ledger'!$B:$B,B23)*Assumptions!$D$5/1000 -> 13.863585 | E23: =Assumptions!$B$5 -> 13.54 | F23: =D23-E23 -> 0.32358544 | G23: =D23/E23-1 -> 0.023898481 | H23: =IF(F23>0.05*E23,"LIST WORTH MORE THAN CAP: BOUGHT WELL, CANNOT AFFORD OWN PLAYERS AT FAIR VALUE",IF(F23<-0.05*E23,"LIST WORTH LESS THAN CAP: PAYING OVERS AS A GROUP","ROUGHLY FAIR VALUE")) -> ROUGHLY FAIR VALUE
A24: 2022 | B24: Essendon | C24: PV | D24: =SUMIFS('Player Ledger'!$E:$E,'Player Ledger'!$A:$A,2022,'Player Ledger'!$B:$B,B24)*Assumptions!$D$5/1000 -> 12.570441 | E24: =Assumptions!$B$5 -> 13.54 | F24: =D24-E24 -> -0.96955895 | G24: =D24/E24-1 -> -0.071607013 | H24: =IF(F24>0.05*E24,"LIST WORTH MORE THAN CAP: BOUGHT WELL, CANNOT AFFORD OWN PLAYERS AT FAIR VALUE",IF(F24<-0.05*E24,"LIST WORTH LESS THAN CAP: PAYING OVERS AS A GROUP","ROUGHLY FAIR VALUE")) -> LIST WORTH LESS THAN CAP: PAYING OVERS AS A GROUP
A25: 2022 | B25: Fremantle | C25: PV | D25: =SUMIFS('Player Ledger'!$E:$E,'Player Ledger'!$A:$A,2022,'Player Ledger'!$B:$B,B25)*Assumptions!$D$5/1000 -> 14.180136 | E25: =Assumptions!$B$5 -> 13.54 | F25: =D25-E25 -> 0.6401364 | G25: =D25/E25-1 -> 0.04727743 | H25: =IF(F25>0.05*E25,"LIST WORTH MORE THAN CAP: BOUGHT WELL, CANNOT AFFORD OWN PLAYERS AT FAIR VALUE",IF(F25<-0.05*E25,"LIST WORTH LESS THAN CAP: PAYING OVERS AS A GROUP","ROUGHLY FAIR VALUE")) -> ROUGHLY FAIR VALUE
A26: 2022 | B26: GWS | C26: PV | D26: =SUMIFS('Player Ledger'!$E:$E,'Player Ledger'!$A:$A,2022,'Player Ledger'!$B:$B,B26)*Assumptions!$D$5/1000 -> 12.48962 | E26: =Assumptions!$B$5 -> 13.54 | F26: =D26-E26 -> -1.0503805 | G26: =D26/E26-1 -> -0.077576106 | H26: =IF(F26>0.05*E26,"LIST WORTH MORE THAN CAP: BOUGHT WELL, CANNOT AFFORD OWN PLAYERS AT FAIR VALUE",IF(F26<-0.05*E26,"LIST WORTH LESS THAN CAP: PAYING OVERS AS A GROUP","ROUGHLY FAIR VALUE")) -> LIST WORTH LESS THAN CAP: PAYING OVERS AS A GROUP
A27: 2022 | B27: Geelong | C27: PV | D27: =SUMIFS('Player Ledger'!$E:$E,'Player Ledger'!$A:$A,2022,'Player Ledger'!$B:$B,B27)*Assumptions!$D$5/1000 -> 15.954169 | E27: =Assumptions!$B$5 -> 13.54 | F27: =D27-E27 -> 2.4141689 | G27: =D27/E27-1 -> 0.17829903 | H27: =IF(F27>0.05*E27,"LIST WORTH MORE THAN CAP: BOUGHT WELL, CANNOT AFFORD OWN PLAYERS AT FAIR VALUE",IF(F27<-0.05*E27,"LIST WORTH LESS THAN CAP: PAYING OVERS AS A GROUP","ROUGHLY FAIR VALUE")) -> LIST WORTH MORE THAN CAP: BOUGHT WELL, CANNOT AFFORD OWN PLAYERS AT FAIR VALUE
A28: 2022 | B28: Gold Coast | C28: PV | D28: =SUMIFS('Player Ledger'!$E:$E,'Player Ledger'!$A:$A,2022,'Player Ledger'!$B:$B,B28)*Assumptions!$D$5/1000 -> 13.928243 | E28: =Assumptions!$B$5 -> 13.54 | F28: =D28-E28 -> 0.38824265 | G28: =D28/E28-1 -> 0.028673756 | H28: =IF(F28>0.05*E28,"LIST WORTH MORE THAN CAP: BOUGHT WELL, CANNOT AFFORD OWN PLAYERS AT FAIR VALUE",IF(F28<-0.05*E28,"LIST WORTH LESS THAN CAP: PAYING OVERS AS A GROUP","ROUGHLY FAIR VALUE")) -> ROUGHLY FAIR VALUE
A29: 2022 | B29: Hawthorn | C29: PV | D29: =SUMIFS('Player Ledger'!$E:$E,'Player Ledger'!$A:$A,2022,'Player Ledger'!$B:$B,B29)*Assumptions!$D$5/1000 -> 12.812906 | E29: =Assumptions!$B$5 -> 13.54 | F29: =D29-E29 -> -0.72709438 | G29: =D29/E29-1 -> -0.053699732 | H29: =IF(F29>0.05*E29,"LIST WORTH MORE THAN CAP: BOUGHT WELL, CANNOT AFFORD OWN PLAYERS AT FAIR VALUE",IF(F29<-0.05*E29,"LIST WORTH LESS THAN CAP: PAYING OVERS AS A GROUP","ROUGHLY FAIR VALUE")) -> LIST WORTH LESS THAN CAP: PAYING OVERS AS A GROUP
A30: 2022 | B30: Melbourne | C30: PV | D30: =SUMIFS('Player Ledger'!$E:$E,'Player Ledger'!$A:$A,2022,'Player Ledger'!$B:$B,B30)*Assumptions!$D$5/1000 -> 14.935818 | E30: =Assumptions!$B$5 -> 13.54 | F30: =D30-E30 -> 1.3958177 | G30: =D30/E30-1 -> 0.10308845 | H30: =IF(F30>0.05*E30,"LIST WORTH MORE THAN CAP: BOUGHT WELL, CANNOT AFFORD OWN PLAYERS AT FAIR VALUE",IF(F30<-0.05*E30,"LIST WORTH LESS THAN CAP: PAYING OVERS AS A GROUP","ROUGHLY FAIR VALUE")) -> LIST WORTH MORE THAN CAP: BOUGHT WELL, CANNOT AFFORD OWN PLAYERS AT FAIR VALUE
A31: 2022 | B31: North Melbourne | C31: PV | D31: =SUMIFS('Player Ledger'!$E:$E,'Player Ledger'!$A:$A,2022,'Player Ledger'!$B:$B,B31)*Assumptions!$D$5/1000 -> 10.470428 | E31: =Assumptions!$B$5 -> 13.54 | F31: =D31-E31 -> -3.0695716 | G31: =D31/E31-1 -> -0.22670396 | H31: =IF(F31>0.05*E31,"LIST WORTH MORE THAN CAP: BOUGHT WELL, CANNOT AFFORD OWN PLAYERS AT FAIR VALUE",IF(F31<-0.05*E31,"LIST WORTH LESS THAN CAP: PAYING OVERS AS A GROUP","ROUGHLY FAIR VALUE")) -> LIST WORTH LESS THAN CAP: PAYING OVERS AS A GROUP
... A37: 2022 | B37: Western Bulldogs | C37: PV | D37: =SUMIFS('Player Ledger'!$E:$E,'Player Ledger'!$A:$A,2022,'Player Ledger'!$B:$B,B37)*Assumptions!$D$5/1000 -> 14.186872 | E37: =Assumptions!$B$5 -> 13.54 | F37: =D37-E37 -> 0.64687153 | G37: =D37/E37-1 -> 0.047774855 | H37: =IF(F37>0.05*E37,"LIST WORTH MORE THAN CAP: BOUGHT WELL, CANNOT AFFORD OWN PLAYERS AT FAIR VALUE",IF(F37<-0.05*E37,"LIST WORTH LESS THAN CAP: PAYING OVERS AS A GROUP","ROUGHLY FAIR VALUE")) -> ROUGHLY FAIR VALUE
A38: 2023 | B38: Adelaide | C38: PV | D38: =SUMIFS('Player Ledger'!$E:$E,'Player Ledger'!$A:$A,2023,'Player Ledger'!$B:$B,B38)*Assumptions!$D$6/1000 -> 16.002635 | E38: =Assumptions!$B$6 -> 15.02 | F38: =D38-E38 -> 0.98263547 | G38: =D38/E38-1 -> 0.065421802 | H38: =IF(F38>0.05*E38,"LIST WORTH MORE THAN CAP: BOUGHT WELL, CANNOT AFFORD OWN PLAYERS AT FAIR VALUE",IF(F38<-0.05*E38,"LIST WORTH LESS THAN CAP: PAYING OVERS AS A GROUP","ROUGHLY FAIR VALUE")) -> LIST WORTH MORE THAN CAP: BOUGHT WELL, CANNOT AFFORD OWN PLAYERS AT FAIR VALUE
A39: 2023 | B39: Brisbane | C39: PV | D39: =SUMIFS('Player Ledger'!$E:$E,'Player Ledger'!$A:$A,2023,'Player Ledger'!$B:$B,B39)*Assumptions!$D$6/1000 -> 16.472465 | E39: =Assumptions!$B$6 -> 15.02 | F39: =D39-E39 -> 1.4524651 | G39: =D39/E39-1 -> 0.096702068 | H39: =IF(F39>0.05*E39,"LIST WORTH MORE THAN CAP: BOUGHT WELL, CANNOT AFFORD OWN PLAYERS AT FAIR VALUE",IF(F39<-0.05*E39,"LIST WORTH LESS THAN CAP: PAYING OVERS AS A GROUP","ROUGHLY FAIR VALUE")) -> LIST WORTH MORE THAN CAP: BOUGHT WELL, CANNOT AFFORD OWN PLAYERS AT FAIR VALUE
A40: 2023 | B40: Carlton | C40: PV | D40: =SUMIFS('Player Ledger'!$E:$E,'Player Ledger'!$A:$A,2023,'Player Ledger'!$B:$B,B40)*Assumptions!$D$6/1000 -> 15.637545 | E40: =Assumptions!$B$6 -> 15.02 | F40: =D40-E40 -> 0.61754495 | G40: =D40/E40-1 -> 0.041114844 | H40: =IF(F40>0.05*E40,"LIST WORTH MORE THAN CAP: BOUGHT WELL, CANNOT AFFORD OWN PLAYERS AT FAIR VALUE",IF(F40<-0.05*E40,"LIST WORTH LESS THAN CAP: PAYING OVERS AS A GROUP","ROUGHLY FAIR VALUE")) -> ROUGHLY FAIR VALUE
A41: 2023 | B41: Collingwood | C41: PV | D41: =SUMIFS('Player Ledger'!$E:$E,'Player Ledger'!$A:$A,2023,'Player Ledger'!$B:$B,B41)*Assumptions!$D$6/1000 -> 16.159744 | E41: =Assumptions!$B$6 -> 15.02 | F41: =D41-E41 -> 1.1397441 | G41: =D41/E41-1 -> 0.075881764 | H41: =IF(F41>0.05*E41,"LIST WORTH MORE THAN CAP: BOUGHT WELL, CANNOT AFFORD OWN PLAYERS AT FAIR VALUE",IF(F41<-0.05*E41,"LIST WORTH LESS THAN CAP: PAYING OVERS AS A GROUP","ROUGHLY FAIR VALUE")) -> LIST WORTH MORE THAN CAP: BOUGHT WELL, CANNOT AFFORD OWN PLAYERS AT FAIR VALUE
A42: 2023 | B42: Essendon | C42: PV | D42: =SUMIFS('Player Ledger'!$E:$E,'Player Ledger'!$A:$A,2023,'Player Ledger'!$B:$B,B42)*Assumptions!$D$6/1000 -> 14.241523 | E42: =Assumptions!$B$6 -> 15.02 | F42: =D42-E42 -> -0.77847738 | G42: =D42/E42-1 -> -0.051829386 | H42: =IF(F42>0.05*E42,"LIST WORTH MORE THAN CAP: BOUGHT WELL, CANNOT AFFORD OWN PLAYERS AT FAIR VALUE",IF(F42<-0.05*E42,"LIST WORTH LESS THAN CAP: PAYING OVERS AS A GROUP","ROUGHLY FAIR VALUE")) -> LIST WORTH LESS THAN CAP: PAYING OVERS AS A GROUP
A43: 2023 | B43: Fremantle | C43: PV | D43: =SUMIFS('Player Ledger'!$E:$E,'Player Ledger'!$A:$A,2023,'Player Ledger'!$B:$B,B43)*Assumptions!$D$6/1000 -> 14.590154 | E43: =Assumptions!$B$6 -> 15.02 | F43: =D43-E43 -> -0.42984587 | G43: =D43/E43-1 -> -0.028618234 | H43: =IF(F43>0.05*E43,"LIST WORTH MORE THAN CAP: BOUGHT WELL, CANNOT AFFORD OWN PLAYERS AT FAIR VALUE",IF(F43<-0.05*E43,"LIST WORTH LESS THAN CAP: PAYING OVERS AS A GROUP","ROUGHLY FAIR VALUE")) -> ROUGHLY FAIR VALUE
A44: 2023 | B44: GWS | C44: PV | D44: =SUMIFS('Player Ledger'!$E:$E,'Player Ledger'!$A:$A,2023,'Player Ledger'!$B:$B,B44)*Assumptions!$D$6/1000 -> 15.706373 | E44: =Assumptions!$B$6 -> 15.02 | F44: =D44-E44 -> 0.68637349 | G44: =D44/E44-1 -> 0.045697303 | H44: =IF(F44>0.05*E44,"LIST WORTH MORE THAN CAP: BOUGHT WELL, CANNOT AFFORD OWN PLAYERS AT FAIR VALUE",IF(F44<-0.05*E44,"LIST WORTH LESS THAN CAP: PAYING OVERS AS A GROUP","ROUGHLY FAIR VALUE")) -> ROUGHLY FAIR VALUE
A45: 2023 | B45: Geelong | C45: PV | D45: =SUMIFS('Player Ledger'!$E:$E,'Player Ledger'!$A:$A,2023,'Player Ledger'!$B:$B,B45)*Assumptions!$D$6/1000 -> 15.64353 | E45: =Assumptions!$B$6 -> 15.02 | F45: =D45-E45 -> 0.62353004 | G45: =D45/E45-1 -> 0.041513318 | H45: =IF(F45>0.05*E45,"LIST WORTH MORE THAN CAP: BOUGHT WELL, CANNOT AFFORD OWN PLAYERS AT FAIR VALUE",IF(F45<-0.05*E45,"LIST WORTH LESS THAN CAP: PAYING OVERS AS A GROUP","ROUGHLY FAIR VALUE")) -> ROUGHLY FAIR VALUE
A46: 2023 | B46: Gold Coast | C46: PV | D46: =SUMIFS('Player Ledger'!$E:$E,'Player Ledger'!$A:$A,2023,'Player Ledger'!$B:$B,B46)*Assumptions!$D$6/1000 -> 14.476437 | E46: =Assumptions!$B$6 -> 15.02 | F46: =D46-E46 -> -0.54356259 | G46: =D46/E46-1 -> -0.036189253 | H46: =IF(F46>0.05*E46,"LIST WORTH MORE THAN CAP: BOUGHT WELL, CANNOT AFFORD OWN PLAYERS AT FAIR VALUE",IF(F46<-0.05*E46,"LIST WORTH LESS THAN CAP: PAYING OVERS AS A GROUP","ROUGHLY FAIR VALUE")) -> ROUGHLY FAIR VALUE
A47: 2023 | B47: Hawthorn | C47: PV | D47: =SUMIFS('Player Ledger'!$E:$E,'Player Ledger'!$A:$A,2023,'Player Ledger'!$B:$B,B47)*Assumptions!$D$6/1000 -> 13.750745 | E47: =Assumptions!$B$6 -> 15.02 | F47: =D47-E47 -> -1.2692548 | G47: =D47/E47-1 -> -0.084504314 | H47: =IF(F47>0.05*E47,"LIST WORTH MORE THAN CAP: BOUGHT WELL, CANNOT AFFORD OWN PLAYERS AT FAIR VALUE",IF(F47<-0.05*E47,"LIST WORTH LESS THAN CAP: PAYING OVERS AS A GROUP","ROUGHLY FAIR VALUE")) -> LIST WORTH LESS THAN CAP: PAYING OVERS AS A GROUP
A48: 2023 | B48: Melbourne | C48: PV | D48: =SUMIFS('Player Ledger'!$E:$E,'Player Ledger'!$A:$A,2023,'Player Ledger'!$B:$B,B48)*Assumptions!$D$6/1000 -> 16.620596 | E48: =Assumptions!$B$6 -> 15.02 | F48: =D48-E48 -> 1.6005961 | G48: =D48/E48-1 -> 0.10656432 | H48: =IF(F48>0.05*E48,"LIST WORTH MORE THAN CAP: BOUGHT WELL, CANNOT AFFORD OWN PLAYERS AT FAIR VALUE",IF(F48<-0.05*E48,"LIST WORTH LESS THAN CAP: PAYING OVERS AS A GROUP","ROUGHLY FAIR VALUE")) -> LIST WORTH MORE THAN CAP: BOUGHT WELL, CANNOT AFFORD OWN PLAYERS AT FAIR VALUE
A49: 2023 | B49: North Melbourne | C49: PV | D49: =SUMIFS('Player Ledger'!$E:$E,'Player Ledger'!$A:$A,2023,'Player Ledger'!$B:$B,B49)*Assumptions!$D$6/1000 -> 12.884403 | E49: =Assumptions!$B$6 -> 15.02 | F49: =D49-E49 -> -2.1355966 | G49: =D49/E49-1 -> -0.14218353 | H49: =IF(F49>0.05*E49,"LIST WORTH MORE THAN CAP: BOUGHT WELL, CANNOT AFFORD OWN PLAYERS AT FAIR VALUE",IF(F49<-0.05*E49,"LIST WORTH LESS THAN CAP: PAYING OVERS AS A GROUP","ROUGHLY FAIR VALUE")) -> LIST WORTH LESS THAN CAP: PAYING OVERS AS A GROUP
... A55: 2023 | B55: Western Bulldogs | C55: PV | D55: =SUMIFS('Player Ledger'!$E:$E,'Player Ledger'!$A:$A,2023,'Player Ledger'!$B:$B,B55)*Assumptions!$D$6/1000 -> 15.54328 | E55: =Assumptions!$B$6 -> 15.02 | F55: =D55-E55 -> 0.52327978 | G55: =D55/E55-1 -> 0.034838867 | H55: =IF(F55>0.05*E55,"LIST WORTH MORE THAN CAP: BOUGHT WELL, CANNOT AFFORD OWN PLAYERS AT FAIR VALUE",IF(F55<-0.05*E55,"LIST WORTH LESS THAN CAP: PAYING OVERS AS A GROUP","ROUGHLY FAIR VALUE")) -> ROUGHLY FAIR VALUE
...

Sheet Headline Mismatches
A1: 2023 SNAPSHOT, MIN 8 GAMES, post stress-test (career floor applied). Live table: Player Ledger.
A3: MOST UNDERPAID (PRODUCTION AHEAD OF REPUTATION)
A4: Club | B4: Player | C4: Games | D4: PV | E4: Career G | F4: Deserved ($K) | G4: Est Band ($K) | H4: Gap ($K)
A5: St Kilda | B5: Mitch Owens | C5: 23 | D5: 5.07 | E5: 7 | F5: 758 | G5: 140 - 250 | H5: 563
A6: Carlton | B6: Charlie Curnow | C6: 26 | D6: 7.48 | E6: 84 | F6: 1119 | G6: 500 - 680 | H6: 529
A7: GWS | B7: Kieren Briggs | C7: 17 | D7: 4.75 | E7: 9 | F7: 711 | G7: 140 - 250 | H7: 516
A8: GWS | B8: Jack Buckley | C8: 26 | D8: 4.73 | E8: 17 | F8: 708 | G8: 140 - 250 | H8: 513
A9: Sydney | B9: Errol Gulden | C9: 24 | D9: 7.29 | E9: 43 | F9: 1090 | G9: 500 - 680 | H9: 500
A10: Adelaide | B10: Mitch Hinge | C10: 22 | D10: 4.52 | E10: 21 | F10: 677 | G10: 140 - 250 | H10: 482
A11: Adelaide | B11: Taylor Walker | C11: 22 | D11: 7.1 | E11: 154 | F11: 1063 | G11: 500 - 680 | H11: 473
A12: Hawthorn | B12: James Worpel | C12: 23 | D12: 5.99 | E12: 79 | F12: 897 | G12: 380 - 500 | H12: 457
A13: Brisbane | B13: Joe Daniher | C13: 26 | D13: 6.95 | E13: 125 | F13: 1040 | G13: 500 - 680 | H13: 450
A14: Richmond | B14: Tim Taranto | C14: 23 | D14: 6.91 | E14: 114 | F14: 1035 | G14: 500 - 680 | H14: 445
A15: Hawthorn | B15: Will Day | C15: 21 | D15: 5.06 | E15: 33 | F15: 757 | G15: 250 - 380 | H15: 442
A16: Gold Coast | B16: Matt Rowell | C16: 23 | D16: 6.83 | E16: 39 | F16: 1022 | G16: 500 - 680 | H16: 432
... A24: Port Adelaide | B24: Connor Rozee | C24: 25 | D24: 6.62 | E24: 81 | F24: 990 | G24: 500 - 680 | H24: 400
A29: MOST OVERPAID (REPUTATION AHEAD OF PRODUCTION)
A30: Club | B30: Player | C30: Games | D30: PV | E30: Career G | F30: Deserved ($K) | G30: Est Band ($K) | H30: Gap ($K)
A31: Brisbane | B31: Jarryd Lyons | C31: 10 | D31: 0.99 | E31: 159 | F31: 149 | G31: 950 - 1300 | H31: -976
A32: Melbourne | B32: Clayton Oliver | C32: 15 | D32: 4.98 | E32: 147 | F32: 746 | G32: 1300 - 1700 | H32: -754
A33: Geelong | B33: Tom Hawkins | C33: 20 | D33: 5.31 | E33: 180 | F33: 794 | G33: 1300 - 1700 | H33: -706
A34: Port Adelaide | B34: Travis Boak | C34: 21 | D34: 3.1 | E34: 172 | F34: 463 | G34: 950 - 1300 | H34: -662
A35: Gold Coast | B35: Touk Miller | C35: 13 | D35: 3.42 | E35: 160 | F35: 511 | G35: 950 - 1300 | H35: -614
A36: Melbourne | B36: Max Gawn | C36: 22 | D36: 6.29 | E36: 155 | F36: 942 | G36: 1300 - 1700 | H36: -558
A37: Carlton | B37: Ed Curnow | C37: 17 | D37: 1.84 | E37: 138 | F37: 276 | G37: 680 - 950 | H37: -539
A38: Essendon | B38: Peter Wright | C38: 10 | D38: 2.11 | E38: 109 | F38: 316 | G38: 680 - 950 | H38: -499
A39: St Kilda | B39: Max King | C39: 11 | D39: 2.43 | E39: 60 | F39: 364 | G39: 680 - 950 | H39: -451
A40: Melbourne | B40: James Harmes | C40: 9 | D40: 1.04 | E40: 143 | F40: 155 | G40: 500 - 680 | H40: -435
A41: Sydney | B41: Lance Franklin | C41: 13 | D41: 2.65 | E41: 137 | F41: 396 | G41: 680 - 950 | H41: -419
A42: Port Adelaide | B42: Ollie Wines | C42: 25 | D42: 4.86 | E42: 154 | F42: 727 | G42: 950 - 1300 | H42: -398
... A50: Richmond | B50: Jayden Short | C50: 16 | D50: 3.36 | E50: 137 | F50: 503 | G50: 680 - 950 | H50: -312
